Workbook

Sheet Summary

Sheet 20260511 Invalid Data
A1: Data Domain | B1: Status March | C1: Status May | D1: KDE | E1: Key Data Element (Thai) | F1: Key Data Element (English) | G1: Src Database | H1: Src Schema | I1: Src Table | J1: Src Column | K1: Business DQ Rules | L1: Prod_ProfilingResult | M1: key | N1: ValidPercentage as of 20260511 | O1: Prod_ThresholdStatus May | P1: Status | Q1: Jobname | R1: Status Test | S1: RootCause | T1: Ticket
A2: Accounting | B2: Cannot be measured | C2: Cannot be measured | D2: KDE00571 | E2: ค่าบำเหน็จ | F2: Commission | G2: sales | H2: salesbenefit_pg | I2: submit_ctrl_detail | J2: amount_pension | K2: Validity | M2: KDE00571sales.salesbenefit_pg.submit_ctrl_detail.amount_pensionValidityAccounting | P2: Cannot be measured | R2: =VLOOKUP(M2,Sheet1!W:X,2,FALSE) -> NOT PASS
A3: Accounting | B3: Cannot be measured | C3: Cannot be measured | D3: KDE00572 | E3: ค่าพาหนะ | F3: Renewal Year Commission | G3: sales | H3: salesbenefit_pg | I3: submit_ctrl_detail | J3: amount_vehicle_fee | K3: Validity | M3: KDE00572sales.salesbenefit_pg.submit_ctrl_detail.amount_vehicle_feeValidityAccounting | P3: Cannot be measured | R3: =VLOOKUP(M3,Sheet1!W:X,2,FALSE) -> NOT PASS
A4: Accounting | B4: Pass | C4: Pass | D4: KDE00383 | E4: อากรสแตมป์ | F4: Revenue Stamp | G4: pos | H4: srvservice | I4: lnrqst | J4: duty | K4: Validity | M4: KDE00383pos.srvservice.lnrqst.dutyValidityAccounting | N4: 100 | O4: Pass | R4: =VLOOKUP(M4,Sheet1!W:X,2,FALSE) -> PASS
A5: Accounting | B5: Pass | C5: Pass | D5: KDE00571 | E5: ค่าบำเหน็จ | F5: Commission | G5: corebiz | H5: ovdebt | I5: debttrndet | J5: benefit | K5: Validity | M5: KDE00571corebiz.ovdebt.debttrndet.benefitValidityAccounting | N5: 100 | O5: Pass | R5: =VLOOKUP(M5,Sheet1!W:X,2,FALSE) -> PASS
A6: Accounting | B6: Pass | C6: Pass | D6: KDE00571 | E6: ค่าบำเหน็จ | F6: Commission | G6: sales | H6: salesbenefit_pg | I6: bank_benefit_detail | J6: amount_commission | K6: Validity | M6: KDE00571sales.salesbenefit_pg.bank_benefit_detail.amount_commissionValidityAccounting | N6: 100 | O6: Pass | R6: =VLOOKUP(M6,Sheet1!W:X,2,FALSE) -> PASS
A7: Accounting | B7: Pass | C7: Pass | D7: KDE00572 | E7: ค่าพาหนะ | F7: Renewal Year Commission | G7: sales | H7: salesbenefit_pg | I7: bank_benefit_detail | J7: amount_renew_commission | K7: Validity | M7: KDE00572sales.salesbenefit_pg.bank_benefit_detail.amount_renew_commissionValidityAccounting | N7: 100 | O7: Pass | R7: =VLOOKUP(M7,Sheet1!W:X,2,FALSE) -> PASS
A8: Accounting | B8: Pass | C8: Pass | D8: KDE00574 | E8: ค่าจัดงานภาค | F8: District Overriding | G8: sales | H8: salesbenefit_pg | I8: bank_benefit_detail | J8: amount_district_ov | K8: Validity | M8: KDE00574sales.salesbenefit_pg.bank_benefit_detail.amount_district_ovValidityAccounting | N8: 100 | O8: Pass | R8: =VLOOKUP(M8,Sheet1!W:X,2,FALSE) -> PASS
A9: Accounting | B9: Pass | C9: Pass | D9: KDE00576 | E9: ค่าจัดงานหน่วย | F9: Unit Overriding | G9: sales | H9: salesbenefit_pg | I9: bank_benefit_detail | J9: amount_unit_ov | K9: Validity | M9: KDE00576sales.salesbenefit_pg.bank_benefit_detail.amount_unit_ovValidityAccounting | N9: 100 | O9: Pass | R9: =VLOOKUP(M9,Sheet1!W:X,2,FALSE) -> PASS
A10: Accounting | B10: Pass | C10: Pass | D10: KDE00578 | E10: ค่าแยกทีมงานภาค | F10: District Spin Off | G10: sales | H10: salesbenefit_pg | I10: bank_benefit_detail | J10: amount_district_so | K10: Validity | M10: KDE00578sales.salesbenefit_pg.bank_benefit_detail.amount_district_soValidityAccounting | N10: 100 | O10: Pass | R10: =VLOOKUP(M10,Sheet1!W:X,2,FALSE) -> PASS
A11: Accounting | B11: Pass | C11: Pass | D11: KDE00579 | E11: ค่าแยกทีมงานศูนย์ | F11: Division Spin Off | G11: sales | H11: salesbenefit_pg | I11: bank_benefit_detail | J11: amount_division_so | K11: Validity | M11: KDE00579sales.salesbenefit_pg.bank_benefit_detail.amount_division_soValidityAccounting | N11: 100 | O11: Pass | R11: =VLOOKUP(M11,Sheet1!W:X,2,FALSE) -> PASS
A12: Accounting | B12: Pass | C12: Pass | D12: KDE00580 | E12: ค่าแยกทีมงานหน่วย | F12: Unit Spin Off | G12: sales | H12: salesbenefit_pg | I12: bank_benefit_detail | J12: amount_unit_so | K12: Validity | M12: KDE00580sales.salesbenefit_pg.bank_benefit_detail.amount_unit_soValidityAccounting | N12: 100 | O12: Pass | R12: =VLOOKUP(M12,Sheet1!W:X,2,FALSE) -> PASS
A13: Accounting | B13: Pass | C13: Pass | D13: KDE00581 | E13: ค่าบริหารเป้าหมายภาค | F13: District Target | G13: sales | H13: salesbenefit_pg | I13: bank_benefit_detail | J13: amount_district_target | K13: Validity | M13: KDE00581sales.salesbenefit_pg.bank_benefit_detail.amount_district_targetValidityAccounting | N13: 100 | O13: Pass | R13: =VLOOKUP(M13,Sheet1!W:X,2,FALSE) -> PASS
A14: Accounting | B14: Pass | C14: Pass | D14: KDE00661 | E14: เลขที่บัญชีธนาคารของตัวแทนในการจ่ายเงิน (payment) - Sales benefit | F14: Bank account number | G14: sales | H14: salesbenefit_pg | I14: master_account_agent | J14: account_no | K14: Completeness | M14: KDE00661sales.salesbenefit_pg.master_account_agent.account_noCompletenessAccounting | N14: 100 | O14: Pass | R14: =VLOOKUP(M14,Sheet1!W:X,2,FALSE) -> PASS
A15: Accounting | B15: Pass | C15: Pass | D15: KDE00661 | E15: เลขที่บัญชีธนาคารของตัวแทนในการจ่ายเงิน (payment) - Sales benefit | F15: Bank account number | G15: sales | H15: salesbenefit_pg | I15: master_account_agent | J15: account_no | K15: Validity | M15: KDE00661sales.salesbenefit_pg.master_account_agent.account_noValidityAccounting | N15: 100 | O15: Pass | R15: =VLOOKUP(M15,Sheet1!W:X,2,FALSE) -> PASS
A16: Claims | B16: Cannot be measured | C16: Cannot be measured | D16: KDE00122 | E16: เลขเรื่องสินไหมประกันชีวิตรายบุคคล | F16: Individual Claim Number | G16: claim | H16: cclaim | I16: claim | J16: orderno,sectioncode | K16: Completeness | M16: KDE00122claim.cclaim.claim.orderno,sectioncodeCompletenessClaims | P16: Sprint40 | R16: =VLOOKUP(M16,Sheet1!W:X,2,FALSE) -> PASS
A17: Claims | B17: Cannot be measured | C17: Cannot be measured | D17: KDE00122 | E17: เลขเรื่องสินไหมประกันชีวิตรายบุคคล | F17: Individual Claim Number | G17: claim | H17: cclaim | I17: claim | J17: orderno,sectioncode | K17: Validity | M17: KDE00122claim.cclaim.claim.orderno,sectioncodeValidityClaims | P17: Sprint40 | R17: =VLOOKUP(M17,Sheet1!W:X,2,FALSE) -> PASS
A18: Claims | B18: Cannot be measured | C18: Cannot be measured | D18: KDE00122 | E18: เลขเรื่องสินไหมประกันชีวิตรายบุคคล | F18: Individual Claim Number | G18: claim | H18: cclaim | I18: eclm | J18: orderno,sectioncode | K18: Validity | M18: KDE00122claim.cclaim.eclm.orderno,sectioncodeValidityClaims | P18: Sprint40 | R18: =VLOOKUP(M18,Sheet1!W:X,2,FALSE) -> PASS
A19: Claims | B19: Cannot be measured | C19: Cannot be measured | D19: KDE00122 | E19: เลขเรื่องสินไหมประกันชีวิตรายบุคคล | F19: Individual Claim Number | G19: claim | H19: cclaim | I19: excinsur | J19: orderno,sectioncode | K19: Validity | M19: KDE00122claim.cclaim.excinsur.orderno,sectioncodeValidityClaims | P19: Sprint40 | R19: =VLOOKUP(M19,Sheet1!W:X,2,FALSE) -> PASS
A20: Claims | B20: Cannot be measured | C20: Cannot be measured | D20: KDE00122 | E20: เลขเรื่องสินไหมประกันชีวิตรายบุคคล | F20: Individual Claim Number | G20: claim | H20: cmortgage | I20: mgclaim | J20: orderno,sectioncode | K20: Validity | M20: KDE00122claim.cmortgage.mgclaim.orderno,sectioncodeValidityClaims | P20: Cannot be measured | R20: =VLOOKUP(M20,Sheet1!W:X,2,FALSE) -> NOT PASS
A21: Claims | B21: Cannot be measured | C21: Cannot be measured | D21: KDE00122 | E21: เลขเรื่องสินไหมประกันชีวิตรายบุคคล | F21: Individual Claim Number | G21: claim | H21: cmortgage | I21: mgfinorder | J21: orderNo,sectionCode | K21: Validity | M21: KDE00122claim.cmortgage.mgfinorder.orderNo,sectionCodeValidityClaims | P21: Sprint40 | R21: =VLOOKUP(M21,Sheet1!W:X,2,FALSE) -> PASS
A22: Claims | B22: Cannot be measured | C22: Cannot be measured | D22: KDE00123 | E22: เลขที่สินไหมสำหรับลูกค้าประกันกลุ่ม | F22: Group Claim Number | G22: policy | H22: cbaac | I22: mclmtrn907 | J22: claimNo | K22: Completeness | M22: KDE00123policy.cbaac.mclmtrn907.claimNoCompletenessClaims | P22: Sprint40 | R22: =VLOOKUP(M22,Sheet1!W:X,2,FALSE) -> PASS
A23: Claims | B23: Cannot be measured | C23: Cannot be measured | D23: KDE00134 | E23: จำนวนเงินที่จ่ายสินไหม | F23: Claim Paid amount | G23: claim | H23: cclaim | I23: dth | J23: payLifeSum,payRiderSum | K23: Completeness | M23: KDE00134claim.cclaim.dth.payLifeSum,payRiderSumCompletenessClaims | P23: Sprint40 | R23: =VLOOKUP(M23,Sheet1!W:X,2,FALSE) -> PASS
A24: Claims | B24: Cannot be measured | C24: Cannot be measured | D24: KDE00134 | E24: จำนวนเงินที่จ่ายสินไหม | F24: Claim Paid amount | G24: policy | H24: mortgage | I24: cert | J24: amount1 | K24: Validity | M24: KDE00134policy.mortgage.cert.amount1ValidityClaims | P24: Sprint40 | R24: =VLOOKUP(M24,Sheet1!W:X,2,FALSE) -> PASS
A25: Claims | B25: Cannot be measured | C25: Cannot be measured | D25: KDE00134 | E25: จำนวนเงินที่จ่ายสินไหม | F25: Claim Paid amount | G25: claim | H25: cclaim | I25: dth | J25: payLifeSum,payRiderSum | K25: Validity | M25: KDE00134claim.cclaim.dth.payLifeSum,payRiderSumValidityClaims | P25: Sprint40 | R25: =VLOOKUP(M25,Sheet1!W:X,2,FALSE) -> PASS
A26: Claims | B26: Cannot be measured | C26: Cannot be measured | D26: KDE00138 | E26: วันที่เกิดเหตุ | F26: occurred date | G26: claim | H26: cclaim | I26: dth | J26: accidentdate | K26: Validity | M26: KDE00138claim.cclaim.dth.accidentdateValidityClaims | P26: Sprint40 | R26: =VLOOKUP(M26,Sheet1!W:X,2,FALSE) -> PASS
A27: Claims | B27: Cannot be measured | C27: Cannot be measured | D27: KDE00138 | E27: วันที่เกิดเหตุ | F27: occurred date | G27: claim | H27: cclaim | I27: iacm | J27: accidentdate | K27: Validity | M27: KDE00138claim.cclaim.iacm.accidentdateValidityClaims | P27: Sprint40 | R27: =VLOOKUP(M27,Sheet1!W:X,2,FALSE) -> PASS
A28: Claims | B28: Cannot be measured | C28: Cannot be measured | D28: KDE00138 | E28: วันที่เกิดเหตุ | F28: occurred date | G28: mbl_db | H28: dbo | I28: after_eclaim | J28: admitdate | K28: Validity | M28: KDE00138mbl_db.dbo.after_eclaim.admitdateValidityClaims | P28: Sprint40 | R28: =VLOOKUP(M28,Sheet1!W:X,2,FALSE) -> PASS
A29: Claims | B29: Cannot be measured | C29: Cannot be measured | D29: KDE00138 | E29: วันที่เกิดเหตุ | F29: occurred date | G29: policy | H29: mortgage | I29: cert | J29: deaddate | K29: Validity | M29: KDE00138policy.mortgage.cert.deaddateValidityClaims | P29: No Result @PROD | Q29: m_PersonDeadDate_Validity_DS403 | R29: =VLOOKUP(M29,Sheet1!W:X,2,FALSE) -> PASS | S29: Incorrect IDQ Mapping Configured | T29: https://tli-edg.atlassian.net/browse/KDEI-551
A30: Claims | B30: Cannot be measured | C30: Cannot be measured | D30: KDE00139 | E30: วันที่เข้ารับการรักษา | F30: Admission date | G30: claim | H30: cclaim | I30: mstwebclaim | J30: admitdate | K30: Completeness | M30: KDE00139claim.cclaim.mstwebclaim.admitdateCompletenessClaims | P30: Sprint40 | R30: =VLOOKUP(M30,Sheet1!W:X,2,FALSE) -> PASS
A31: Claims | B31: Cannot be measured | C31: Cannot be measured | D31: KDE00139 | E31: วันที่เข้ารับการรักษา | F31: Admission date | G31: group_life | H31: glife | I31: hclaim | J31: st_healdate | K31: Completeness | M31: KDE00139group_life.glife.hclaim.st_healdateCompletenessClaims | P31: Sprint40 | R31: =VLOOKUP(M31,Sheet1!W:X,2,FALSE) -> PASS
A32: Claims | B32: Cannot be measured | C32: Cannot be measured | D32: KDE00139 | E32: วันที่เข้ารับการรักษา | F32: Admission date | G32: claim | H32: cclaim | I32: mstwebclaim | J32: admitdate | K32: Validity | M32: KDE00139claim.cclaim.mstwebclaim.admitdateValidityClaims | P32: Sprint40 | R32: =VLOOKUP(M32,Sheet1!W:X,2,FALSE) -> PASS
A33: Claims | B33: Cannot be measured | C33: Cannot be measured | D33: KDE00141 | E33: วันที่อนุมัติสินไหม | F33: Claim Approved date | G33: claim | H33: cmortgage | I33: mgfinorder | J33: claimOkDate | K33: Completeness | M33: KDE00141claim.cmortgage.mgfinorder.claimOkDateCompletenessClaims | P33: Sprint40 | R33: =VLOOKUP(M33,Sheet1!W:X,2,FALSE) -> PASS
A34: Claims | B34: Cannot be measured | C34: Cannot be measured | D34: KDE00142 | E34: วันเดือนปีที่รับเอกสารเคลม | F34: Receive Document Date | G34: group_life | H34: glife | I34: claim | J34: recvdate | K34: Validity | M34: KDE00142group_life.glife.claim.recvdateValidityClaims | P34: Sprint40 | R34: =VLOOKUP(M34,Sheet1!W:X,2,FALSE) -> PASS
A35: Claims | B35: Cannot be measured | C35: Cannot be measured | D35: KDE00143 | E35: เลขที่รับเรื่องในการเรียกร้องสินไหมสำหรับลูกค้าประกันกลุ่ม | F35: Receive CLaim Number | G35: policy | H35: cbaac | I35: mclmrcv907 | J35: receiveNo | K35: Completeness | M35: KDE00143policy.cbaac.mclmrcv907.receiveNoCompletenessClaims | P35: Cannot be measured | R35: =VLOOKUP(M35,Sheet1!W:X,2,FALSE) -> NOT PASS
A36: Claims | B36: Invalid Data | C36: Invalid Data | D36: KDE00125 | E36: เหตุผลที่ปฏิเสธการจ่ายสินไหม | F36: Reject reason | G36: group_life | H36: glife | I36: rejclaim | J36: reject_cause | K36: Completeness | L36: Contact EDM | M36: KDE00125group_life.glife.rejclaim.reject_causeCompletenessClaims | N36: 99.95712 | O36: Fail - Invalid Data | P36: Sprint40 | R36: =VLOOKUP(M36,Sheet1!W:X,2,FALSE) -> PASS
A37: Claims | B37: Invalid Data | C37: Invalid Data | D37: KDE00133 | E37: ค่ารักษาพยาบาลตามใบเสร็จ | F37: Incurred amount | G37: group_life | H37: glife | I37: hclaimrcv | J37: amount | K37: Validity | L37: Contact EDM | M37: KDE00133group_life.glife.hclaimrcv.amountValidityClaims | N37: 99.999962 | O37: Fail - Invalid Data | P37: Sprint40 | R37: =VLOOKUP(M37,Sheet1!W:X,2,FALSE) -> PASS
A38: Claims | B38: Invalid Data | C38: Invalid Data | D38: KDE00138 | E38: วันที่เกิดเหตุ | F38: occurred date | G38: claim | H38: cclaim | I38: mstwebclaim | J38: accidentdate | K38: Validity | L38: Contact EDM | M38: KDE00138claim.cclaim.mstwebclaim.accidentdateValidityClaims | N38: 99.952532 | O38: Fail - Invalid Data | P38: Sprint40 | R38: =VLOOKUP(M38,Sheet1!W:X,2,FALSE) -> PASS
A39: Claims | B39: Invalid Data | C39: Invalid Data | D39: KDE00138 | E39: วันที่เกิดเหตุ | F39: occurred date | G39: claim | H39: cclaim | I39: oacm | J39: accidentdate | K39: Validity | L39: Contact EDM | M39: KDE00138claim.cclaim.oacm.accidentdateValidityClaims | N39: 99.998309 | O39: Fail - Invalid Data | P39: Sprint40 | R39: =VLOOKUP(M39,Sheet1!W:X,2,FALSE) -> PASS
A40: Claims | B40: Invalid Data | C40: Invalid Data | D40: KDE00139 | E40: วันที่เข้ารับการรักษา | F40: Admission date | G40: group_life | H40: glife | I40: hclaim | J40: st_healdate | K40: Validity | L40: Contact EDM | M40: KDE00139group_life.glife.hclaim.st_healdateValidityClaims | N40: 99.999709 | O40: Fail - Invalid Data | P40: Sprint40 | R40: =VLOOKUP(M40,Sheet1!W:X,2,FALSE) -> PASS
...

Sheet 20260316 Invalid Data
A1: Data Domain | B1: Status | C1: KDE | D1: Key Data Element (Thai) | E1: Key Data Element (English) | F1: Src Database | G1: Src Schema | H1: Src Table | I1: Src Column | J1: Business DQ Rules | K1: Prod_ProfilingResult | L1: IssueCategory | M1: IssueSubCategory | N1: ValidPercentage | O1: Prod_ThresholdStatus
A2: Accounting | B2: Cannot be measured | C2: KDE00571 | D2: ค่าบำเหน็จ | E2: Commission | F2: sales | G2: salesbenefit_pg | H2: submit_ctrl_detail | I2: amount_pension | J2: Validity
A3: Accounting | B3: Cannot be measured | C3: KDE00572 | D3: ค่าพาหนะ | E3: Renewal Year Commission | F3: sales | G3: salesbenefit_pg | H3: submit_ctrl_detail | I3: amount_vehicle_fee | J3: Validity
A4: Accounting | B4: Pass | C4: KDE00383 | D4: อากรสแตมป์ | E4: Revenue Stamp | F4: pos | G4: srvservice | H4: lnrqst | I4: duty | J4: Validity | K4: DS629_StampDutyAmount_Validity_prf | O4: Pass
A5: Accounting | B5: Pass | C5: KDE00571 | D5: ค่าบำเหน็จ | E5: Commission | F5: corebiz | G5: ovdebt | H5: debttrndet | I5: benefit | J5: Validity | K5: DS146_CommissionAmount_Validity_prf | O5: Pass
A6: Accounting | B6: Pass | C6: KDE00571 | D6: ค่าบำเหน็จ | E6: Commission | F6: sales | G6: salesbenefit_pg | H6: bank_benefit_detail | I6: amount_commission | J6: Validity | K6: DS1165_CommissionAmount_Validity_prf | O6: Pass
A7: Accounting | B7: Pass | C7: KDE00572 | D7: ค่าพาหนะ | E7: Renewal Year Commission | F7: sales | G7: salesbenefit_pg | H7: bank_benefit_detail | I7: amount_renew_commission | J7: Validity | K7: DS1166_RenewalYearCommissionAmount_Validity_prf | O7: Pass
A8: Accounting | B8: Pass | C8: KDE00574 | D8: ค่าจัดงานภาค | E8: District Overriding | F8: sales | G8: salesbenefit_pg | H8: bank_benefit_detail | I8: amount_district_ov | J8: Validity | K8: DS1168_DistrictOverridingAmount_Validity_prf | O8: Pass
A9: Accounting | B9: Pass | C9: KDE00576 | D9: ค่าจัดงานหน่วย | E9: Unit Overriding | F9: sales | G9: salesbenefit_pg | H9: bank_benefit_detail | I9: amount_unit_ov | J9: Validity | K9: DS1170_UnitOverridingAmount_Validity_prf | O9: Pass
A10: Accounting | B10: Pass | C10: KDE00578 | D10: ค่าแยกทีมงานภาค | E10: District Spin Off | F10: sales | G10: salesbenefit_pg | H10: bank_benefit_detail | I10: amount_district_so | J10: Validity | K10: DS1171_DistrictSpinOffAmount_Validity_prf | O10: Pass
A11: Accounting | B11: Pass | C11: KDE00579 | D11: ค่าแยกทีมงานศูนย์ | E11: Division Spin Off | F11: sales | G11: salesbenefit_pg | H11: bank_benefit_detail | I11: amount_division_so | J11: Validity | K11: DS1172_DivisionSpinOffAmount_Validity_prf | O11: Pass
A12: Accounting | B12: Pass | C12: KDE00580 | D12: ค่าแยกทีมงานหน่วย | E12: Unit Spin Off | F12: sales | G12: salesbenefit_pg | H12: bank_benefit_detail | I12: amount_unit_so | J12: Validity | K12: DS1173_UnitSpinOffAmount_Validity_prf | O12: Pass
A13: Accounting | B13: Pass | C13: KDE00581 | D13: ค่าบริหารเป้าหมายภาค | E13: District Target | F13: sales | G13: salesbenefit_pg | H13: bank_benefit_detail | I13: amount_district_target | J13: Validity | K13: DS1174_DistrictTargetAmount_Validity_prf | O13: Pass
A14: Accounting | B14: Pass | C14: KDE00661 | D14: เลขที่บัญชีธนาคารของตัวแทนในการจ่ายเงิน (payment) - Sales benefit | E14: Bank account number | F14: sales | G14: salesbenefit_pg | H14: master_account_agent | I14: account_no | J14: Completeness | K14: DS709_BankAccountNumber_Completeness_prf | O14: Pass
A15: Accounting | B15: Pass | C15: KDE00661 | D15: เลขที่บัญชีธนาคารของตัวแทนในการจ่ายเงิน (payment) - Sales benefit | E15: Bank account number | F15: sales | G15: salesbenefit_pg | H15: master_account_agent | I15: account_no | J15: Validity | K15: DS709_BankAccountNumber_Validity_prf | O15: Pass
A16: Claims | B16: Cannot be measured | C16: KDE00122 | D16: เลขเรื่องสินไหมประกันชีวิตรายบุคคล | E16: Individual Claim Number | F16: claim | G16: cclaim | H16: claim | I16: orderno,sectioncode | J16: Completeness
A17: Claims | B17: Cannot be measured | C17: KDE00122 | D17: เลขเรื่องสินไหมประกันชีวิตรายบุคคล | E17: Individual Claim Number | F17: claim | G17: cclaim | H17: claim | I17: orderno,sectioncode | J17: Validity
A18: Claims | B18: Cannot be measured | C18: KDE00122 | D18: เลขเรื่องสินไหมประกันชีวิตรายบุคคล | E18: Individual Claim Number | F18: claim | G18: cclaim | H18: eclm | I18: orderno,sectioncode | J18: Validity
A19: Claims | B19: Cannot be measured | C19: KDE00122 | D19: เลขเรื่องสินไหมประกันชีวิตรายบุคคล | E19: Individual Claim Number | F19: claim | G19: cclaim | H19: excinsur | I19: orderno,sectioncode | J19: Validity
A20: Claims | B20: Cannot be measured | C20: KDE00122 | D20: เลขเรื่องสินไหมประกันชีวิตรายบุคคล | E20: Individual Claim Number | F20: claim | G20: cmortgage | H20: mgclaim | I20: orderno,sectioncode | J20: Validity
A21: Claims | B21: Cannot be measured | C21: KDE00122 | D21: เลขเรื่องสินไหมประกันชีวิตรายบุคคล | E21: Individual Claim Number | F21: claim | G21: cmortgage | H21: mgfinorder | I21: orderNo,sectionCode | J21: Validity
A22: Claims | B22: Cannot be measured | C22: KDE00123 | D22: เลขที่สินไหมสำหรับลูกค้าประกันกลุ่ม | E22: Group Claim Number | F22: policy | G22: cbaac | H22: mclmtrn907 | I22: claimNo | J22: Completeness | K22: DS402_GroupClaimNumber_Completeness_prf | O22: No Data Found
A23: Claims | B23: Cannot be measured | C23: KDE00134 | D23: จำนวนเงินที่จ่ายสินไหม | E23: Claim Paid amount | F23: claim | G23: cclaim | H23: dth | I23: payLifeSum,payRiderSum | J23: Completeness
A24: Claims | B24: Cannot be measured | C24: KDE00134 | D24: จำนวนเงินที่จ่ายสินไหม | E24: Claim Paid amount | F24: policy | G24: mortgage | H24: cert | I24: amount1 | J24: Validity
A25: Claims | B25: Cannot be measured | C25: KDE00134 | D25: จำนวนเงินที่จ่ายสินไหม | E25: Claim Paid amount | F25: claim | G25: cclaim | H25: dth | I25: payLifeSum,payRiderSum | J25: Validity
A26: Claims | B26: Cannot be measured | C26: KDE00138 | D26: วันที่เกิดเหตุ | E26: occurred date | F26: claim | G26: cclaim | H26: dth | I26: accidentdate | J26: Validity
A27: Claims | B27: Cannot be measured | C27: KDE00138 | D27: วันที่เกิดเหตุ | E27: occurred date | F27: claim | G27: cclaim | H27: iacm | I27: accidentdate | J27: Validity
A28: Claims | B28: Cannot be measured | C28: KDE00138 | D28: วันที่เกิดเหตุ | E28: occurred date | F28: mbl_db | G28: dbo | H28: after_eclaim | I28: admitdate | J28: Validity
A29: Claims | B29: Cannot be measured | C29: KDE00138 | D29: วันที่เกิดเหตุ | E29: occurred date | F29: policy | G29: mortgage | H29: cert | I29: deaddate | J29: Validity
A30: Claims | B30: Cannot be measured | C30: KDE00139 | D30: วันที่เข้ารับการรักษา | E30: Admission date | F30: claim | G30: cclaim | H30: mstwebclaim | I30: admitdate | J30: Completeness
A31: Claims | B31: Cannot be measured | C31: KDE00139 | D31: วันที่เข้ารับการรักษา | E31: Admission date | F31: group_life | G31: glife | H31: hclaim | I31: st_healdate | J31: Completeness
A32: Claims | B32: Cannot be measured | C32: KDE00139 | D32: วันที่เข้ารับการรักษา | E32: Admission date | F32: claim | G32: cclaim | H32: mstwebclaim | I32: admitdate | J32: Validity
A33: Claims | B33: Cannot be measured | C33: KDE00141 | D33: วันที่อนุมัติสินไหม | E33: Claim Approved date | F33: claim | G33: cmortgage | H33: mgfinorder | I33: claimOkDate | J33: Completeness | K33: DS74_ClaimApprovalDate_Completeness_prf | O33: No Data Found
A34: Claims | B34: Cannot be measured | C34: KDE00142 | D34: วันเดือนปีที่รับเอกสารเคลม | E34: Receive Document Date | F34: group_life | G34: glife | H34: claim | I34: recvdate | J34: Validity
A35: Claims | B35: Cannot be measured | C35: KDE00143 | D35: เลขที่รับเรื่องในการเรียกร้องสินไหมสำหรับลูกค้าประกันกลุ่ม | E35: Receive CLaim Number | F35: policy | G35: cbaac | H35: mclmrcv907 | I35: receiveNo | J35: Completeness
A36: Claims | B36: Invalid Data | C36: KDE00125 | D36: เหตุผลที่ปฏิเสธการจ่ายสินไหม | E36: Reject reason | F36: group_life | G36: glife | H36: rejclaim | I36: reject_cause | J36: Completeness | K36: DS300_ClaimRejectReason_Completeness_prf | L36: Completeness | M36: Missing required fields | N36: 99.95712 | O36: Fail - Invalid Data
A37: Claims | B37: Invalid Data | C37: KDE00133 | D37: ค่ารักษาพยาบาลตามใบเสร็จ | E37: Incurred amount | F37: group_life | G37: glife | H37: hclaimrcv | I37: amount | J37: Validity | K37: DS306_IncurredAmount_Validity_prf | L37: Validity | M37: Out‑of‑range numerical values | N37: 99.999962 | O37: Fail - Invalid Data
A38: Claims | B38: Invalid Data | C38: KDE00138 | D38: วันที่เกิดเหตุ | E38: occurred date | F38: claim | G38: cclaim | H38: mstwebclaim | I38: accidentdate | J38: Validity | K38: DS70_AccidentOccurredDate_Validity_prf | L38: Validity | M38: Invalid data format | N38: 99.952532 | O38: Fail - Invalid Data
A39: Claims | B39: Invalid Data | C39: KDE00138 | D39: วันที่เกิดเหตุ | E39: occurred date | F39: claim | G39: cclaim | H39: oacm | I39: accidentdate | J39: Validity | K39: DS71_AccidentOccurredDate_Validity_prf | L39: Validity | M39: Invalid data format | N39: 99.998309 | O39: Fail - Invalid Data
A40: Claims | B40: Invalid Data | C40: KDE00139 | D40: วันที่เข้ารับการรักษา | E40: Admission date | F40: group_life | G40: glife | H40: hclaim | I40: st_healdate | J40: Validity | K40: DS308_AdmissionDate_Validity_prf | L40: Validity | M40: Invalid data format | N40: 99.999709 | O40: Fail - Invalid Data
...

Sheet Sheet3
A3: Status May | B3: Count of KDE | C3: countIF | E3: Status May | F3: KDE | G3: Count of KDE
A4: Cannot be measured | B4: 215 | C4: 75 | E4: Cannot be measured | F4: KDE00001 | G4: 1
A5: Invalid Data | B5: 163 | C5: 75 | F5: KDE00005 | G5: 34
A6: Pass | B6: 491 | C6: 137 | F6: KDE00007 | G6: 6 | J6: Status Test | K6: CountIf of KDE
A7: (blank) | B7: 1 | C7: 1 | F7: KDE00008 | G7: 1 | J7: FIXED | K7: 12
A8: Grand Total | B8: 870 | F8: KDE00014 | G8: 1 | J8: NOT PASS | K8: 39
F9: KDE00016 | G9: 21 | J9: PASS | K9: 172
C10: =SUM(C4:C9) -> 288 | F10: KDE00025 | G10: 1 | J10: Pass with Condition | K10: 19
F11: KDE00058 | G11: 1 | J11: Ready | K11: 5
F12: KDE00063 | G12: 2 | J12: (blank) | K12: 1
F13: KDE00093 | G13: 1 | J13: Grand Total | K13: =SUM(K7:K12) -> 248
F14: KDE00104 | G14: 1
F15: KDE00121 | G15: 2
F16: KDE00122 | G16: 6
F17: KDE00123 | G17: 1
F18: KDE00134 | G18: 3
F19: KDE00136 | G19: 1
F20: KDE00138 | G20: 4
F21: KDE00139 | G21: 3
F22: KDE00141 | G22: 1
F23: KDE00142 | G23: 1
F24: KDE00143 | G24: 1
F25: KDE00152 | G25: 1
... F78: KDE00802 | G78: 2
E79: Cannot be measured Total | G79: 215
E80: Invalid Data | G80: 163
E81: Pass | G81: 491
E82: (blank) | F82: KDE00514 | G82: 1
F83: (blank)
E84: (blank) Total | G84: 1
E85: Grand Total | G85: 870

Sheet xxx
A1: Data Domain | B1: Status March | C1: Status May | D1: Status Jun | E1: xxx | F1: KDE | G1: Key Data Element (Thai) | H1: Key Data Element (English) | I1: Src Database | J1: Src Schema | K1: Src Table | L1: Src Column | M1: Business DQ Rules | N1: Prod_ProfilingResult | O1: key | P1: ValidPercentage as of 20260601 | R1: Prod_ThresholdStatus Jun | S1: Status | T1: Jobname | U1: Status Test | V1: RootCause | W1: Ticket
A2: Accounting | B2: Cannot be measured | C2: Cannot be measured | D2: Cannot be measured | F2: KDE00571 | G2: ค่าบำเหน็จ | H2: Commission | I2: sales | J2: salesbenefit_pg | K2: submit_ctrl_detail | L2: amount_pension | M2: Validity | O2: KDE00571sales.salesbenefit_pg.submit_ctrl_detail.amount_pensionValidityAccounting | P2: =VLOOKUP(O2,Sheet6!K:L,2,FALSE) -> #N/A | S2: Cannot be measured | U2: =VLOOKUP(O2,Sheet1!W:X,2,FALSE) -> NOT PASS | V2: Check data in partioned tables: cunderwrite.phoneYYMM
A3: Accounting | B3: Cannot be measured | C3: Cannot be measured | D3: Cannot be measured | F3: KDE00572 | G3: ค่าพาหนะ | H3: Renewal Year Commission | I3: sales | J3: salesbenefit_pg | K3: submit_ctrl_detail | L3: amount_vehicle_fee | M3: Validity | O3: KDE00572sales.salesbenefit_pg.submit_ctrl_detail.amount_vehicle_feeValidityAccounting | P3: =VLOOKUP(O3,Sheet6!K:L,2,FALSE) -> #N/A | S3: Cannot be measured | U3: =VLOOKUP(O3,Sheet1!W:X,2,FALSE) -> NOT PASS
A4: Accounting | B4: Pass | C4: Pass | D4: Pass | F4: KDE00383 | G4: อากรสแตมป์ | H4: Revenue Stamp | I4: pos | J4: srvservice | K4: lnrqst | L4: duty | M4: Validity | O4: KDE00383pos.srvservice.lnrqst.dutyValidityAccounting | P4: =VLOOKUP(O4,Sheet6!K:L,2,FALSE) -> 100 | Q4: Pass | R4: Pass | U4: =VLOOKUP(O4,Sheet1!W:X,2,FALSE) -> PASS
A5: Accounting | B5: Pass | C5: Pass | D5: Pass | F5: KDE00571 | G5: ค่าบำเหน็จ | H5: Commission | I5: corebiz | J5: ovdebt | K5: debttrndet | L5: benefit | M5: Validity | O5: KDE00571corebiz.ovdebt.debttrndet.benefitValidityAccounting | P5: =VLOOKUP(O5,Sheet6!K:L,2,FALSE) -> 100 | R5: Pass | U5: =VLOOKUP(O5,Sheet1!W:X,2,FALSE) -> PASS
A6: Accounting | B6: Pass | C6: Pass | D6: Pass | F6: KDE00571 | G6: ค่าบำเหน็จ | H6: Commission | I6: sales | J6: salesbenefit_pg | K6: bank_benefit_detail | L6: amount_commission | M6: Validity | O6: KDE00571sales.salesbenefit_pg.bank_benefit_detail.amount_commissionValidityAccounting | P6: =VLOOKUP(O6,Sheet6!K:L,2,FALSE) -> 100 | R6: Pass | U6: =VLOOKUP(O6,Sheet1!W:X,2,FALSE) -> PASS
A7: Accounting | B7: Pass | C7: Pass | D7: Pass | F7: KDE00572 | G7: ค่าพาหนะ | H7: Renewal Year Commission | I7: sales | J7: salesbenefit_pg | K7: bank_benefit_detail | L7: amount_renew_commission | M7: Validity | O7: KDE00572sales.salesbenefit_pg.bank_benefit_detail.amount_renew_commissionValidityAccounting | P7: =VLOOKUP(O7,Sheet6!K:L,2,FALSE) -> 100 | R7: Pass | U7: =VLOOKUP(O7,Sheet1!W:X,2,FALSE) -> PASS
A8: Accounting | B8: Pass | C8: Pass | D8: Pass | F8: KDE00574 | G8: ค่าจัดงานภาค | H8: District Overriding | I8: sales | J8: salesbenefit_pg | K8: bank_benefit_detail | L8: amount_district_ov | M8: Validity | O8: KDE00574sales.salesbenefit_pg.bank_benefit_detail.amount_district_ovValidityAccounting | P8: =VLOOKUP(O8,Sheet6!K:L,2,FALSE) -> 100 | R8: Pass | U8: =VLOOKUP(O8,Sheet1!W:X,2,FALSE) -> PASS
A9: Accounting | B9: Pass | C9: Pass | D9: Pass | F9: KDE00576 | G9: ค่าจัดงานหน่วย | H9: Unit Overriding | I9: sales | J9: salesbenefit_pg | K9: bank_benefit_detail | L9: amount_unit_ov | M9: Validity | O9: KDE00576sales.salesbenefit_pg.bank_benefit_detail.amount_unit_ovValidityAccounting | P9: =VLOOKUP(O9,Sheet6!K:L,2,FALSE) -> 100 | R9: Pass | U9: =VLOOKUP(O9,Sheet1!W:X,2,FALSE) -> PASS
A10: Accounting | B10: Pass | C10: Pass | D10: Pass | F10: KDE00578 | G10: ค่าแยกทีมงานภาค | H10: District Spin Off | I10: sales | J10: salesbenefit_pg | K10: bank_benefit_detail | L10: amount_district_so | M10: Validity | O10: KDE00578sales.salesbenefit_pg.bank_benefit_detail.amount_district_soValidityAccounting | P10: =VLOOKUP(O10,Sheet6!K:L,2,FALSE) -> 100 | R10: Pass | U10: =VLOOKUP(O10,Sheet1!W:X,2,FALSE) -> PASS
A11: Accounting | B11: Pass | C11: Pass | D11: Pass | F11: KDE00579 | G11: ค่าแยกทีมงานศูนย์ | H11: Division Spin Off | I11: sales | J11: salesbenefit_pg | K11: bank_benefit_detail | L11: amount_division_so | M11: Validity | O11: KDE00579sales.salesbenefit_pg.bank_benefit_detail.amount_division_soValidityAccounting | P11: =VLOOKUP(O11,Sheet6!K:L,2,FALSE) -> 100 | R11: Pass | U11: =VLOOKUP(O11,Sheet1!W:X,2,FALSE) -> PASS
A12: Accounting | B12: Pass | C12: Pass | D12: Pass | F12: KDE00580 | G12: ค่าแยกทีมงานหน่วย | H12: Unit Spin Off | I12: sales | J12: salesbenefit_pg | K12: bank_benefit_detail | L12: amount_unit_so | M12: Validity | O12: KDE00580sales.salesbenefit_pg.bank_benefit_detail.amount_unit_soValidityAccounting | P12: =VLOOKUP(O12,Sheet6!K:L,2,FALSE) -> 100 | R12: Pass | U12: =VLOOKUP(O12,Sheet1!W:X,2,FALSE) -> PASS
A13: Accounting | B13: Pass | C13: Pass | D13: Pass | F13: KDE00581 | G13: ค่าบริหารเป้าหมายภาค | H13: District Target | I13: sales | J13: salesbenefit_pg | K13: bank_benefit_detail | L13: amount_district_target | M13: Validity | O13: KDE00581sales.salesbenefit_pg.bank_benefit_detail.amount_district_targetValidityAccounting | P13: =VLOOKUP(O13,Sheet6!K:L,2,FALSE) -> 100 | R13: Pass | U13: =VLOOKUP(O13,Sheet1!W:X,2,FALSE) -> PASS
A14: Accounting | B14: Pass | C14: Pass | D14: Pass | F14: KDE00661 | G14: เลขที่บัญชีธนาคารของตัวแทนในการจ่ายเงิน (payment) - Sales benefit | H14: Bank account number | I14: sales | J14: salesbenefit_pg | K14: master_account_agent | L14: account_no | M14: Completeness | O14: KDE00661sales.salesbenefit_pg.master_account_agent.account_noCompletenessAccounting | P14: =VLOOKUP(O14,Sheet6!K:L,2,FALSE) -> 100 | R14: Pass | U14: =VLOOKUP(O14,Sheet1!W:X,2,FALSE) -> PASS
A15: Accounting | B15: Pass | C15: Pass | D15: Pass | F15: KDE00661 | G15: เลขที่บัญชีธนาคารของตัวแทนในการจ่ายเงิน (payment) - Sales benefit | H15: Bank account number | I15: sales | J15: salesbenefit_pg | K15: master_account_agent | L15: account_no | M15: Validity | O15: KDE00661sales.salesbenefit_pg.master_account_agent.account_noValidityAccounting | P15: =VLOOKUP(O15,Sheet6!K:L,2,FALSE) -> 100 | R15: Pass | U15: =VLOOKUP(O15,Sheet1!W:X,2,FALSE) -> PASS
A16: Claims | B16: Cannot be measured | C16: Cannot be measured | D16: Cannot be measured | F16: KDE00122 | G16: เลขเรื่องสินไหมประกันชีวิตรายบุคคล | H16: Individual Claim Number | I16: claim | J16: cmortgage | K16: mgclaim | L16: orderno,sectioncode | M16: Validity | O16: KDE00122claim.cmortgage.mgclaim.orderno,sectioncodeValidityClaims | P16: =VLOOKUP(O16,Sheet6!K:L,2,FALSE) -> #N/A | S16: Cannot be measured | U16: =VLOOKUP(O16,Sheet1!W:X,2,FALSE) -> NOT PASS
A17: Claims | B17: Cannot be measured | C17: Cannot be measured | D17: Cannot be measured | F17: KDE00122 | G17: เลขเรื่องสินไหมประกันชีวิตรายบุคคล | H17: Individual Claim Number | I17: claim | J17: cmortgage | K17: mgfinorder | L17: orderNo,sectionCode | M17: Validity | O17: KDE00122claim.cmortgage.mgfinorder.ClaimNumberValidityClaims | P17: =VLOOKUP(O17,Sheet6!K:L,2,FALSE) -> #N/A | S17: Sprint40 | U17: PASS
A18: Claims | B18: Cannot be measured | C18: Cannot be measured | D18: Cannot be measured | F18: KDE00123 | G18: เลขที่สินไหมสำหรับลูกค้าประกันกลุ่ม | H18: Group Claim Number | I18: policy | J18: cbaac | K18: mclmtrn907 | L18: claimNo | M18: Completeness | O18: KDE00123policy.cbaac.mclmtrn907.claimNoCompletenessClaims | P18: =VLOOKUP(O18,Sheet6!K:L,2,FALSE) -> #N/A | S18: Sprint40 | U18: =VLOOKUP(O18,Sheet1!W:X,2,FALSE) -> PASS
A19: Claims | B19: Cannot be measured | C19: Cannot be measured | D19: Cannot be measured | F19: KDE00134 | G19: จำนวนเงินที่จ่ายสินไหม | H19: Claim Paid amount | I19: claim | J19: cclaim | K19: dth | L19: payLifeSum,payRiderSum | M19: Validity | O19: KDE00134claim.cclaim.dth.ClaimPaidAmountValidityClaims | P19: =VLOOKUP(O19,Sheet6!K:L,2,FALSE) -> #N/A | S19: Sprint40 No Result @PROD | U19: PASS
A20: Claims | B20: Cannot be measured | C20: Cannot be measured | D20: Cannot be measured | F20: KDE00138 | G20: วันที่เกิดเหตุ | H20: occurred date | I20: policy | J20: mortgage | K20: cert | L20: deaddate | M20: Validity | O20: KDE00138policy.mortgage.cert.deaddateValidityClaims | P20: =VLOOKUP(O20,Sheet6!K:L,2,FALSE) -> #N/A | S20: No Result @PROD | T20: m_PersonDeadDate_Validity_DS403 | U20: =VLOOKUP(O20,Sheet1!W:X,2,FALSE) -> PASS
A21: Claims | B21: Cannot be measured | C21: Cannot be measured | D21: Cannot be measured | F21: KDE00141 | G21: วันที่อนุมัติสินไหม | H21: Claim Approved date | I21: claim | J21: cmortgage | K21: mgfinorder | L21: claimOkDate | M21: Completeness | O21: KDE00141claim.cmortgage.mgfinorder.claimOkDateCompletenessClaims | P21: =VLOOKUP(O21,Sheet6!K:L,2,FALSE) -> #N/A | S21: Sprint40 | U21: =VLOOKUP(O21,Sheet1!W:X,2,FALSE) -> PASS
A22: Claims | B22: Cannot be measured | C22: Cannot be measured | D22: Cannot be measured | F22: KDE00143 | G22: เลขที่รับเรื่องในการเรียกร้องสินไหมสำหรับลูกค้าประกันกลุ่ม | H22: Receive CLaim Number | I22: policy | J22: cbaac | K22: mclmrcv907 | L22: receiveNo | M22: Completeness | O22: KDE00143policy.cbaac.mclmrcv907.receiveNoCompletenessClaims | P22: =VLOOKUP(O22,Sheet6!K:L,2,FALSE) -> #N/A | S22: Cannot be measured | U22: =VLOOKUP(O22,Sheet1!W:X,2,FALSE) -> NOT PASS
A23: Claims | B23: Cannot be measured | C23: Cannot be measured | D23: Invalid Data | F23: KDE00122 | G23: เลขเรื่องสินไหมประกันชีวิตรายบุคคล | H23: Individual Claim Number | I23: claim | J23: cclaim | K23: claim | L23: orderno,sectioncode | M23: Completeness | N23: DQ Measurement Result - Claims.xlsx | O23: KDE00122claim.cclaim.claim.ClaimNumberCompletenessClaims | P23: =VLOOKUP(O23,Sheet6!K:L,2,FALSE) -> 99.999936 | R23: Fail - Invalid Data | S23: Sprint40 | U23: PASS
A24: Claims | B24: Cannot be measured | C24: Cannot be measured | D24: Invalid Data | F24: KDE00122 | G24: เลขเรื่องสินไหมประกันชีวิตรายบุคคล | H24: Individual Claim Number | I24: claim | J24: cclaim | K24: claim | L24: orderno,sectioncode | M24: Validity | N24: DQ Measurement Result - Claims.xlsx | O24: KDE00122claim.cclaim.claim.ClaimNumberValidityClaims | P24: =VLOOKUP(O24,Sheet6!K:L,2,FALSE) -> 99.999743 | R24: Fail - Invalid Data | S24: Sprint40 | U24: PASS
A25: Claims | B25: Cannot be measured | C25: Cannot be measured | D25: Invalid Data | F25: KDE00122 | G25: เลขเรื่องสินไหมประกันชีวิตรายบุคคล | H25: Individual Claim Number | I25: claim | J25: cclaim | K25: excinsur | L25: orderno,sectioncode | M25: Validity | N25: DQ Measurement Result - Claims.xlsx | O25: KDE00122claim.cclaim.excinsur.ClaimNumberValidityClaims | P25: =VLOOKUP(O25,Sheet6!K:L,2,FALSE) -> 99.993299 | R25: Fail - Invalid Data | S25: Sprint40 | U25: PASS
A26: Claims | B26: Invalid Data | C26: Invalid Data | D26: Invalid Data | F26: KDE00125 | G26: เหตุผลที่ปฏิเสธการจ่ายสินไหม | H26: Reject reason | I26: group_life | J26: glife | K26: rejclaim | L26: reject_cause | M26: Completeness | N26: DQ Measurement Result - Claims.xlsx | O26: KDE00125group_life.glife.rejclaim.reject_causeCompletenessClaims | P26: =VLOOKUP(O26,Sheet6!K:L,2,FALSE) -> 99.957348 | R26: Fail - Invalid Data | S26: Sprint40 | U26: =VLOOKUP(O26,Sheet1!W:X,2,FALSE) -> PASS
A27: Claims | B27: Invalid Data | C27: Invalid Data | D27: Invalid Data | F27: KDE00133 | G27: ค่ารักษาพยาบาลตามใบเสร็จ | H27: Incurred amount | I27: group_life | J27: glife | K27: hclaimrcv | L27: amount | M27: Validity | N27: DQ Measurement Result - Claims.xlsx | O27: KDE00133group_life.glife.hclaimrcv.amountValidityClaims | P27: =VLOOKUP(O27,Sheet6!K:L,2,FALSE) -> 99.999963 | R27: Fail - Invalid Data | S27: Sprint40 | U27: =VLOOKUP(O27,Sheet1!W:X,2,FALSE) -> PASS
A28: Claims | B28: Cannot be measured | C28: Cannot be measured | D28: Invalid Data | F28: KDE00134 | G28: จำนวนเงินที่จ่ายสินไหม | H28: Claim Paid amount | I28: claim | J28: cclaim | K28: dth | L28: payLifeSum,payRiderSum | M28: Completeness | N28: DQ Measurement Result - Claims.xlsx | O28: KDE00134claim.cclaim.dth.ClaimPaidAmountCompletenessClaims | P28: =VLOOKUP(O28,Sheet6!K:L,2,FALSE) -> 99.997295 | R28: Fail - Invalid Data | S28: Sprint40 | U28: PASS
A29: Claims | B29: Cannot be measured | C29: Cannot be measured | D29: Invalid Data | F29: KDE00138 | G29: วันที่เกิดเหตุ | H29: occurred date | I29: claim | J29: cclaim | K29: iacm | L29: accidentdate | M29: Validity | N29: DQ Measurement Result - Claims.xlsx | O29: KDE00138claim.cclaim.iacm.accidentdateValidityClaims | P29: =VLOOKUP(O29,Sheet6!K:L,2,FALSE) -> 99.991083 | R29: Fail - Invalid Data | S29: Sprint40 | U29: =VLOOKUP(O29,Sheet1!W:X,2,FALSE) -> PASS
A30: Claims | B30: Cannot be measured | C30: Cannot be measured | D30: Invalid Data | F30: KDE00138 | G30: วันที่เกิดเหตุ | H30: occurred date | I30: mbl_db | J30: dbo | K30: after_eclaim | L30: admitdate | M30: Validity | N30: DQ Measurement Result - Claims.xlsx | O30: KDE00138mbl_db.dbo.after_eclaim.admitdateValidityClaims | P30: =VLOOKUP(O30,Sheet6!K:L,2,FALSE) -> 99.962999 | R30: Fail - Invalid Data | S30: Sprint40 | U30: =VLOOKUP(O30,Sheet1!W:X,2,FALSE) -> PASS
A31: Claims | B31: Invalid Data | C31: Invalid Data | D31: Invalid Data | F31: KDE00138 | G31: วันที่เกิดเหตุ | H31: occurred date | I31: claim | J31: cclaim | K31: mstwebclaim | L31: accidentdate | M31: Validity | N31: DQ Measurement Result - Claims.xlsx | O31: KDE00138claim.cclaim.mstwebclaim.accidentdateValidityClaims | P31: =VLOOKUP(O31,Sheet6!K:L,2,FALSE) -> 99.954311 | R31: Fail - Invalid Data | S31: Sprint40 | U31: =VLOOKUP(O31,Sheet1!W:X,2,FALSE) -> PASS
A32: Claims | B32: Invalid Data | C32: Invalid Data | D32: Invalid Data | F32: KDE00138 | G32: วันที่เกิดเหตุ | H32: occurred date | I32: claim | J32: cclaim | K32: oacm | L32: accidentdate | M32: Validity | N32: DQ Measurement Result - Claims.xlsx | O32: KDE00138claim.cclaim.oacm.accidentdateValidityClaims | P32: =VLOOKUP(O32,Sheet6!K:L,2,FALSE) -> 99.998286 | R32: Fail - Invalid Data | S32: Sprint40 | U32: =VLOOKUP(O32,Sheet1!W:X,2,FALSE) -> PASS
A33: Claims | B33: Cannot be measured | C33: Cannot be measured | D33: Invalid Data | F33: KDE00139 | G33: วันที่เข้ารับการรักษา | H33: Admission date | I33: claim | J33: cclaim | K33: mstwebclaim | L33: admitdate | M33: Completeness | N33: DQ Measurement Result - Claims.xlsx | O33: KDE00139claim.cclaim.mstwebclaim.admitdateCompletenessClaims | P33: =VLOOKUP(O33,Sheet6!K:L,2,FALSE) -> 92.642859 | R33: Fail - Invalid Data | S33: Sprint40 | U33: =VLOOKUP(O33,Sheet1!W:X,2,FALSE) -> PASS
A34: Claims | B34: Cannot be measured | C34: Cannot be measured | D34: Invalid Data | F34: KDE00139 | G34: วันที่เข้ารับการรักษา | H34: Admission date | I34: group_life | J34: glife | K34: hclaim | L34: st_healdate | M34: Completeness | N34: DQ Measurement Result - Claims.xlsx | O34: KDE00139group_life.glife.hclaim.st_healdateCompletenessClaims | P34: =VLOOKUP(O34,Sheet6!K:L,2,FALSE) -> 99.999278 | R34: Fail - Invalid Data | S34: Sprint40 | U34: =VLOOKUP(O34,Sheet1!W:X,2,FALSE) -> PASS
A35: Claims | B35: Cannot be measured | C35: Cannot be measured | D35: Invalid Data | F35: KDE00139 | G35: วันที่เข้ารับการรักษา | H35: Admission date | I35: claim | J35: cclaim | K35: mstwebclaim | L35: admitdate | M35: Validity | N35: DQ Measurement Result - Claims.xlsx | O35: KDE00139claim.cclaim.mstwebclaim.admitdateValidityClaims | P35: =VLOOKUP(O35,Sheet6!K:L,2,FALSE) -> 99.999199 | R35: Fail - Invalid Data | S35: Sprint40 | U35: =VLOOKUP(O35,Sheet1!W:X,2,FALSE) -> PASS
A36: Claims | B36: Invalid Data | C36: Invalid Data | D36: Invalid Data | F36: KDE00139 | G36: วันที่เข้ารับการรักษา | H36: Admission date | I36: group_life | J36: glife | K36: hclaim | L36: st_healdate | M36: Validity | N36: DQ Measurement Result - Claims.xlsx | O36: KDE00139group_life.glife.hclaim.st_healdateValidityClaims | P36: =VLOOKUP(O36,Sheet6!K:L,2,FALSE) -> 99.999716 | R36: Fail - Invalid Data | S36: Sprint40 | U36: =VLOOKUP(O36,Sheet1!W:X,2,FALSE) -> PASS
A37: Claims | B37: Invalid Data | C37: Invalid Data | D37: Invalid Data | F37: KDE00140 | G37: วันเดือนปีที่จ่ายเงินสินไหม | H37: Payment Date | I37: group_life | J37: glife | K37: claim | L37: paydate | M37: Completeness | N37: DQ Measurement Result - Claims.xlsx | O37: KDE00140group_life.glife.claim.paydateCompletenessClaims | P37: =VLOOKUP(O37,Sheet6!K:L,2,FALSE) -> 99.871195 | R37: Fail - Invalid Data | S37: Sprint40 | U37: =VLOOKUP(O37,Sheet1!W:X,2,FALSE) -> PASS
A38: Claims | B38: Invalid Data | C38: Invalid Data | D38: Invalid Data | F38: KDE00140 | G38: วันเดือนปีที่จ่ายเงินสินไหม | H38: Payment Date | I38: group_life | J38: glife | K38: hclaim | L38: paydate | M38: Completeness | N38: DQ Measurement Result - Claims.xlsx | O38: KDE00140group_life.glife.hclaim.paydateCompletenessClaims | P38: =VLOOKUP(O38,Sheet6!K:L,2,FALSE) -> 99.999977 | R38: Fail - Invalid Data | S38: Sprint40 | U38: =VLOOKUP(O38,Sheet1!W:X,2,FALSE) -> PASS
A39: Claims | B39: Invalid Data | C39: Invalid Data | D39: Invalid Data | F39: KDE00140 | G39: วันเดือนปีที่จ่ายเงินสินไหม | H39: Payment Date | I39: group_life | J39: glife | K39: medclaim | L39: paydate | M39: Completeness | N39: DQ Measurement Result - Claims.xlsx | O39: KDE00140group_life.glife.medclaim.paydateCompletenessClaims | P39: =VLOOKUP(O39,Sheet6!K:L,2,FALSE) -> 99.977093 | R39: Fail - Invalid Data | S39: Sprint40 | U39: =VLOOKUP(O39,Sheet1!W:X,2,FALSE) -> PASS
A40: Claims | B40: Invalid Data | C40: Invalid Data | D40: Invalid Data | F40: KDE00140 | G40: วันเดือนปีที่จ่ายเงินสินไหม | H40: Payment Date | I40: group_life | J40: glife | K40: hclaim | L40: paydate | M40: Validity | N40: DQ Measurement Result - Claims.xlsx | O40: KDE00140group_life.glife.hclaim.paydateValidityClaims | P40: =VLOOKUP(O40,Sheet6!K:L,2,FALSE) -> 99.999571 | R40: Fail - Invalid Data | S40: Sprint40 | U40: =VLOOKUP(O40,Sheet1!W:X,2,FALSE) -> PASS
...

Sheet Sheet6
A1: KDENumber | B1: DataDomain | C1: Dimension | D1: DataField | E1: TestedRows | F1: AnomalyRows | G1: ValidRows | H1: ValidPercentage | I1: Threshold | J1: ThresholdStatus | K1: key
A2: KDE00734 | B2: Customer | C2: Validity | D2: dfl.dfl.beneficiary.identifyid | E2: 5 | F2: 5 | G2: 0 | H2: 0 | I2: 100 | J2: Fail | K2: =A2&D2&C2&B2 -> KDE00734dfl.dfl.beneficiary.identifyidValidityCustomer | L2: =H2 -> 0
A3: KDE00409 | B3: Customer | C3: Completeness | D3: dfl.dfl.mcaapplications.fatcaagree | E3: 40851 | F3: 40851 | G3: 0 | H3: 0 | I3: 100 | J3: Fail | K3: =A3&D3&C3&B3 -> KDE00409dfl.dfl.mcaapplications.fatcaagreeCompletenessCustomer | L3: =H3 -> 0
A4: KDE00413 | B4: Customer | C4: Validity | D4: pos.collection.gwcollection.card_number | E4: 1 | F4: 1 | G4: 0 | H4: 0 | I4: 100 | J4: Fail | K4: =A4&D4&C4&B4 -> KDE00413pos.collection.gwcollection.card_numberValidityCustomer | L4: =H4 -> 0
A5: KDE00223 | B5: Insurance/Policy | C5: Completeness | D5: tlprompt.public.quotation.savingpremium | E5: 4748538 | F5: 4746250 | G5: 2288 | H5: 0.048183251 | I5: 100 | J5: Fail | K5: =A5&D5&C5&B5 -> KDE00223tlprompt.public.quotation.savingpremiumCompletenessInsurance/Policy | L5: =H5 -> 0.048183251
A6: KDE00007 | B6: Customer | C6: Completeness | D6: tlprompt.public.payment.personidtax | E6: 1192179 | F6: 1188521 | G6: 3658 | H6: 0.30683312 | I6: 100 | J6: Fail | K6: =A6&D6&C6&B6 -> KDE00007tlprompt.public.payment.personidtaxCompletenessCustomer | L6: =H6 -> 0.30683312
A7: KDE00092 | B7: Customer | C7: Validity | D7: policy.mstpolicy.whlmast.occupationtype | E7: 4811 | F7: 4789 | G7: 22 | H7: 0.45728539 | I7: 100 | J7: Fail | K7: =A7&D7&C7&B7 -> KDE00092policy.mstpolicy.whlmast.occupationtypeValidityCustomer | L7: =H7 -> 0.45728539
A8: KDE00008 | B8: Customer | C8: Completeness | D8: tlprompt.public.prospect.passport | E8: 788211 | F8: 783459 | G8: 4752 | H8: 0.60288425 | I8: 100 | J8: Fail | K8: =A8&D8&C8&B8 -> KDE00008tlprompt.public.prospect.passportCompletenessCustomer | L8: =H8 -> 0.60288425
A9: KDE00256 | B9: Insurance/Policy | C9: Completeness | D9: policy.mortgage.cert.certno | E9: 1214344 | F9: 1199520 | G9: 14824 | H9: 1.2207414 | I9: 100 | J9: Fail | K9: =A9&D9&C9&B9 -> KDE00256policy.mortgage.cert.certnoCompletenessInsurance/Policy | L9: =H9 -> 1.2207414
A10: KDE00228 | B10: Insurance/Policy | C10: Completeness | D10: tlprompt.public.quotation.topuppremium | E10: 4748538 | F10: 4470238 | G10: 278300 | H10: 5.8607512 | I10: 100 | J10: Fail | K10: =A10&D10&C10&B10 -> KDE00228tlprompt.public.quotation.topuppremiumCompletenessInsurance/Policy | L10: =H10 -> 5.8607512
A11: KDE00005 | B11: Customer | C11: Completeness | D11: common_db.dbo.tb_prospect.citizen_id | E11: 1079 | F11: 800 | G11: 279 | H11: 25.857275 | I11: 100 | J11: Fail | K11: =A11&D11&C11&B11 -> KDE00005common_db.dbo.tb_prospect.citizen_idCompletenessCustomer | L11: =H11 -> 25.857275
A12: KDE00802 | B12: Customer | C12: Validity | D12: claim.claimbook.claimpaymentreceiver.citizenid | E12: 4507795 | F12: 3212059 | G12: 1295736 | H12: 28.744342 | I12: 100 | J12: Fail | K12: =A12&D12&C12&B12 -> KDE00802claim.claimbook.claimpaymentreceiver.citizenidValidityCustomer | L12: =H12 -> 28.744342
A13: KDE00005 | B13: Customer | C13: Validity | D13: pos.newservice.fatca.referenceid | E13: 60 | F13: 41 | G13: 19 | H13: 31.666667 | I13: 100 | J13: Fail | K13: =A13&D13&C13&B13 -> KDE00005pos.newservice.fatca.referenceidValidityCustomer | L13: =H13 -> 31.666667
... A796: KDE00363 | B796: Finance | C796: Validity | D796: underwrite.cunderwrite.job.psreceivedate | E796: 29510 | F796: 0 | G796: 29510 | H796: 100 | I796: 100 | J796: Pass | K796: =A796&D796&C796&B796 -> KDE00363underwrite.cunderwrite.job.psreceivedateValidityFinance | L796: =H796 -> 100

Sheet 20260601 Invalid Data
A1: Data Domain | B1: Status March | C1: Status May | D1: Status Jun | E1: KDE | F1: Key Data Element (Thai) | G1: Key Data Element (English) | H1: Src Database | I1: Src Schema | J1: Src Table | K1: Src Column | L1: Business DQ Rules | M1: Prod_ProfilingResult | N1: key | O1: ValidPercentage as of 20260601 | Q1: Prod_ThresholdStatus Jun | R1: Status | S1: Jobname | T1: Status Test | U1: RootCause | V1: Ticket
A2: Accounting | B2: Cannot be measured | C2: Cannot be measured | D2: Cannot be measured | E2: KDE00571 | F2: ค่าบำเหน็จ | G2: Commission | H2: sales | I2: salesbenefit_pg | J2: submit_ctrl_detail | K2: amount_pension | L2: Validity | N2: KDE00571sales.salesbenefit_pg.submit_ctrl_detail.amount_pensionValidityAccounting | R2: Cannot be measured | T2: =VLOOKUP(N2,Sheet1!W:X,2,FALSE) -> NOT PASS | U2: Check data in partioned tables: cunderwrite.phoneYYMM
A3: Accounting | B3: Cannot be measured | C3: Cannot be measured | D3: Cannot be measured | E3: KDE00572 | F3: ค่าพาหนะ | G3: Renewal Year Commission | H3: sales | I3: salesbenefit_pg | J3: submit_ctrl_detail | K3: amount_vehicle_fee | L3: Validity | N3: KDE00572sales.salesbenefit_pg.submit_ctrl_detail.amount_vehicle_feeValidityAccounting | R3: Cannot be measured | T3: =VLOOKUP(N3,Sheet1!W:X,2,FALSE) -> NOT PASS
A4: Accounting | B4: Pass | C4: Pass | D4: Pass | E4: KDE00383 | F4: อากรสแตมป์ | G4: Revenue Stamp | H4: pos | I4: srvservice | J4: lnrqst | K4: duty | L4: Validity | N4: KDE00383pos.srvservice.lnrqst.dutyValidityAccounting | O4: 100 | Q4: Pass | T4: =VLOOKUP(N4,Sheet1!W:X,2,FALSE) -> PASS
A5: Accounting | B5: Pass | C5: Pass | D5: Pass | E5: KDE00571 | F5: ค่าบำเหน็จ | G5: Commission | H5: corebiz | I5: ovdebt | J5: debttrndet | K5: benefit | L5: Validity | N5: KDE00571corebiz.ovdebt.debttrndet.benefitValidityAccounting | O5: 100 | Q5: Pass | T5: =VLOOKUP(N5,Sheet1!W:X,2,FALSE) -> PASS
A6: Accounting | B6: Pass | C6: Pass | D6: Pass | E6: KDE00571 | F6: ค่าบำเหน็จ | G6: Commission | H6: sales | I6: salesbenefit_pg | J6: bank_benefit_detail | K6: amount_commission | L6: Validity | N6: KDE00571sales.salesbenefit_pg.bank_benefit_detail.amount_commissionValidityAccounting | O6: 100 | Q6: Pass | T6: =VLOOKUP(N6,Sheet1!W:X,2,FALSE) -> PASS
A7: Accounting | B7: Pass | C7: Pass | D7: Pass | E7: KDE00572 | F7: ค่าพาหนะ | G7: Renewal Year Commission | H7: sales | I7: salesbenefit_pg | J7: bank_benefit_detail | K7: amount_renew_commission | L7: Validity | N7: KDE00572sales.salesbenefit_pg.bank_benefit_detail.amount_renew_commissionValidityAccounting | O7: 100 | Q7: Pass | T7: =VLOOKUP(N7,Sheet1!W:X,2,FALSE) -> PASS
A8: Accounting | B8: Pass | C8: Pass | D8: Pass | E8: KDE00574 | F8: ค่าจัดงานภาค | G8: District Overriding | H8: sales | I8: salesbenefit_pg | J8: bank_benefit_detail | K8: amount_district_ov | L8: Validity | N8: KDE00574sales.salesbenefit_pg.bank_benefit_detail.amount_district_ovValidityAccounting | O8: 100 | Q8: Pass | T8: =VLOOKUP(N8,Sheet1!W:X,2,FALSE) -> PASS
A9: Accounting | B9: Pass | C9: Pass | D9: Pass | E9: KDE00576 | F9: ค่าจัดงานหน่วย | G9: Unit Overriding | H9: sales | I9: salesbenefit_pg | J9: bank_benefit_detail | K9: amount_unit_ov | L9: Validity | N9: KDE00576sales.salesbenefit_pg.bank_benefit_detail.amount_unit_ovValidityAccounting | O9: 100 | Q9: Pass | T9: =VLOOKUP(N9,Sheet1!W:X,2,FALSE) -> PASS
A10: Accounting | B10: Pass | C10: Pass | D10: Pass | E10: KDE00578 | F10: ค่าแยกทีมงานภาค | G10: District Spin Off | H10: sales | I10: salesbenefit_pg | J10: bank_benefit_detail | K10: amount_district_so | L10: Validity | N10: KDE00578sales.salesbenefit_pg.bank_benefit_detail.amount_district_soValidityAccounting | O10: 100 | Q10: Pass | T10: =VLOOKUP(N10,Sheet1!W:X,2,FALSE) -> PASS
A11: Accounting | B11: Pass | C11: Pass | D11: Pass | E11: KDE00579 | F11: ค่าแยกทีมงานศูนย์ | G11: Division Spin Off | H11: sales | I11: salesbenefit_pg | J11: bank_benefit_detail | K11: amount_division_so | L11: Validity | N11: KDE00579sales.salesbenefit_pg.bank_benefit_detail.amount_division_soValidityAccounting | O11: 100 | Q11: Pass | T11: =VLOOKUP(N11,Sheet1!W:X,2,FALSE) -> PASS
A12: Accounting | B12: Pass | C12: Pass | D12: Pass | E12: KDE00580 | F12: ค่าแยกทีมงานหน่วย | G12: Unit Spin Off | H12: sales | I12: salesbenefit_pg | J12: bank_benefit_detail | K12: amount_unit_so | L12: Validity | N12: KDE00580sales.salesbenefit_pg.bank_benefit_detail.amount_unit_soValidityAccounting | O12: 100 | Q12: Pass | T12: =VLOOKUP(N12,Sheet1!W:X,2,FALSE) -> PASS
A13: Accounting | B13: Pass | C13: Pass | D13: Pass | E13: KDE00581 | F13: ค่าบริหารเป้าหมายภาค | G13: District Target | H13: sales | I13: salesbenefit_pg | J13: bank_benefit_detail | K13: amount_district_target | L13: Validity | N13: KDE00581sales.salesbenefit_pg.bank_benefit_detail.amount_district_targetValidityAccounting | O13: 100 | Q13: Pass | T13: =VLOOKUP(N13,Sheet1!W:X,2,FALSE) -> PASS
A14: Accounting | B14: Pass | C14: Pass | D14: Pass | E14: KDE00661 | F14: เลขที่บัญชีธนาคารของตัวแทนในการจ่ายเงิน (payment) - Sales benefit | G14: Bank account number | H14: sales | I14: salesbenefit_pg | J14: master_account_agent | K14: account_no | L14: Completeness | N14: KDE00661sales.salesbenefit_pg.master_account_agent.account_noCompletenessAccounting | O14: 100 | Q14: Pass | T14: =VLOOKUP(N14,Sheet1!W:X,2,FALSE) -> PASS
A15: Accounting | B15: Pass | C15: Pass | D15: Pass | E15: KDE00661 | F15: เลขที่บัญชีธนาคารของตัวแทนในการจ่ายเงิน (payment) - Sales benefit | G15: Bank account number | H15: sales | I15: salesbenefit_pg | J15: master_account_agent | K15: account_no | L15: Validity | N15: KDE00661sales.salesbenefit_pg.master_account_agent.account_noValidityAccounting | O15: 100 | Q15: Pass | T15: =VLOOKUP(N15,Sheet1!W:X,2,FALSE) -> PASS
A16: Claims | B16: Cannot be measured | C16: Cannot be measured | D16: Cannot be measured | E16: KDE00122 | F16: เลขเรื่องสินไหมประกันชีวิตรายบุคคล | G16: Individual Claim Number | H16: claim | I16: cmortgage | J16: mgclaim | K16: orderno,sectioncode | L16: Validity | N16: KDE00122claim.cmortgage.mgclaim.orderno,sectioncodeValidityClaims | R16: Cannot be measured | T16: =VLOOKUP(N16,Sheet1!W:X,2,FALSE) -> NOT PASS
A17: Claims | B17: Cannot be measured | C17: Cannot be measured | D17: Cannot be measured | E17: KDE00122 | F17: เลขเรื่องสินไหมประกันชีวิตรายบุคคล | G17: Individual Claim Number | H17: claim | I17: cmortgage | J17: mgfinorder | K17: orderNo,sectionCode | L17: Validity | N17: KDE00122claim.cmortgage.mgfinorder.ClaimNumberValidityClaims | R17: Sprint40 | T17: PASS
A18: Claims | B18: Cannot be measured | C18: Cannot be measured | D18: Cannot be measured | E18: KDE00123 | F18: เลขที่สินไหมสำหรับลูกค้าประกันกลุ่ม | G18: Group Claim Number | H18: policy | I18: cbaac | J18: mclmtrn907 | K18: claimNo | L18: Completeness | N18: KDE00123policy.cbaac.mclmtrn907.claimNoCompletenessClaims | R18: Sprint40 | T18: =VLOOKUP(N18,Sheet1!W:X,2,FALSE) -> PASS
A19: Claims | B19: Cannot be measured | C19: Cannot be measured | D19: Cannot be measured | E19: KDE00134 | F19: จำนวนเงินที่จ่ายสินไหม | G19: Claim Paid amount | H19: claim | I19: cclaim | J19: dth | K19: payLifeSum,payRiderSum | L19: Validity | N19: KDE00134claim.cclaim.dth.ClaimPaidAmountValidityClaims | R19: Sprint40 No Result @PROD | T19: PASS
A20: Claims | B20: Cannot be measured | C20: Cannot be measured | D20: Cannot be measured | E20: KDE00138 | F20: วันที่เกิดเหตุ | G20: occurred date | H20: policy | I20: mortgage | J20: cert | K20: deaddate | L20: Validity | N20: KDE00138policy.mortgage.cert.deaddateValidityClaims | R20: No Result @PROD | S20: m_PersonDeadDate_Validity_DS403 | T20: =VLOOKUP(N20,Sheet1!W:X,2,FALSE) -> PASS
A21: Claims | B21: Cannot be measured | C21: Cannot be measured | D21: Cannot be measured | E21: KDE00141 | F21: วันที่อนุมัติสินไหม | G21: Claim Approved date | H21: claim | I21: cmortgage | J21: mgfinorder | K21: claimOkDate | L21: Completeness | N21: KDE00141claim.cmortgage.mgfinorder.claimOkDateCompletenessClaims | R21: Sprint40 | T21: =VLOOKUP(N21,Sheet1!W:X,2,FALSE) -> PASS
A22: Claims | B22: Cannot be measured | C22: Cannot be measured | D22: Cannot be measured | E22: KDE00143 | F22: เลขที่รับเรื่องในการเรียกร้องสินไหมสำหรับลูกค้าประกันกลุ่ม | G22: Receive CLaim Number | H22: policy | I22: cbaac | J22: mclmrcv907 | K22: receiveNo | L22: Completeness | N22: KDE00143policy.cbaac.mclmrcv907.receiveNoCompletenessClaims | R22: Cannot be measured | T22: =VLOOKUP(N22,Sheet1!W:X,2,FALSE) -> NOT PASS
A23: Claims | B23: Cannot be measured | C23: Cannot be measured | D23: Invalid Data | E23: KDE00122 | F23: เลขเรื่องสินไหมประกันชีวิตรายบุคคล | G23: Individual Claim Number | H23: claim | I23: cclaim | J23: claim | K23: orderno,sectioncode | L23: Completeness | M23: DQ Measurement Result - Claims.xlsx | N23: KDE00122claim.cclaim.claim.ClaimNumberCompletenessClaims | O23: 99.999936 | Q23: Fail - Invalid Data | R23: Sprint40 | T23: PASS
A24: Claims | B24: Cannot be measured | C24: Cannot be measured | D24: Invalid Data | E24: KDE00122 | F24: เลขเรื่องสินไหมประกันชีวิตรายบุคคล | G24: Individual Claim Number | H24: claim | I24: cclaim | J24: claim | K24: orderno,sectioncode | L24: Validity | M24: DQ Measurement Result - Claims.xlsx | N24: KDE00122claim.cclaim.claim.ClaimNumberValidityClaims | O24: 99.999743 | Q24: Fail - Invalid Data | R24: Sprint40 | T24: PASS
A25: Claims | B25: Cannot be measured | C25: Cannot be measured | D25: Invalid Data | E25: KDE00122 | F25: เลขเรื่องสินไหมประกันชีวิตรายบุคคล | G25: Individual Claim Number | H25: claim | I25: cclaim | J25: excinsur | K25: orderno,sectioncode | L25: Validity | M25: DQ Measurement Result - Claims.xlsx | N25: KDE00122claim.cclaim.excinsur.ClaimNumberValidityClaims | O25: 99.993299 | Q25: Fail - Invalid Data | R25: Sprint40 | T25: PASS
A26: Claims | B26: Invalid Data | C26: Invalid Data | D26: Invalid Data | E26: KDE00125 | F26: เหตุผลที่ปฏิเสธการจ่ายสินไหม | G26: Reject reason | H26: group_life | I26: glife | J26: rejclaim | K26: reject_cause | L26: Completeness | M26: DQ Measurement Result - Claims.xlsx | N26: KDE00125group_life.glife.rejclaim.reject_causeCompletenessClaims | O26: 99.957348 | Q26: Fail - Invalid Data | R26: Sprint40 | T26: =VLOOKUP(N26,Sheet1!W:X,2,FALSE) -> PASS
A27: Claims | B27: Invalid Data | C27: Invalid Data | D27: Invalid Data | E27: KDE00133 | F27: ค่ารักษาพยาบาลตามใบเสร็จ | G27: Incurred amount | H27: group_life | I27: glife | J27: hclaimrcv | K27: amount | L27: Validity | M27: DQ Measurement Result - Claims.xlsx | N27: KDE00133group_life.glife.hclaimrcv.amountValidityClaims | O27: 99.999963 | Q27: Fail - Invalid Data | R27: Sprint40 | T27: =VLOOKUP(N27,Sheet1!W:X,2,FALSE) -> PASS
A28: Claims | B28: Cannot be measured | C28: Cannot be measured | D28: Invalid Data | E28: KDE00134 | F28: จำนวนเงินที่จ่ายสินไหม | G28: Claim Paid amount | H28: claim | I28: cclaim | J28: dth | K28: payLifeSum,payRiderSum | L28: Completeness | M28: DQ Measurement Result - Claims.xlsx | N28: KDE00134claim.cclaim.dth.ClaimPaidAmountCompletenessClaims | O28: 99.997295 | Q28: Fail - Invalid Data | R28: Sprint40 | T28: PASS
A29: Claims | B29: Cannot be measured | C29: Cannot be measured | D29: Invalid Data | E29: KDE00138 | F29: วันที่เกิดเหตุ | G29: occurred date | H29: claim | I29: cclaim | J29: iacm | K29: accidentdate | L29: Validity | M29: DQ Measurement Result - Claims.xlsx | N29: KDE00138claim.cclaim.iacm.accidentdateValidityClaims | O29: 99.991083 | Q29: Fail - Invalid Data | R29: Sprint40 | T29: =VLOOKUP(N29,Sheet1!W:X,2,FALSE) -> PASS
A30: Claims | B30: Cannot be measured | C30: Cannot be measured | D30: Invalid Data | E30: KDE00138 | F30: วันที่เกิดเหตุ | G30: occurred date | H30: mbl_db | I30: dbo | J30: after_eclaim | K30: admitdate | L30: Validity | M30: DQ Measurement Result - Claims.xlsx | N30: KDE00138mbl_db.dbo.after_eclaim.admitdateValidityClaims | O30: 99.962999 | Q30: Fail - Invalid Data | R30: Sprint40 | T30: =VLOOKUP(N30,Sheet1!W:X,2,FALSE) -> PASS
A31: Claims | B31: Invalid Data | C31: Invalid Data | D31: Invalid Data | E31: KDE00138 | F31: วันที่เกิดเหตุ | G31: occurred date | H31: claim | I31: cclaim | J31: mstwebclaim | K31: accidentdate | L31: Validity | M31: DQ Measurement Result - Claims.xlsx | N31: KDE00138claim.cclaim.mstwebclaim.accidentdateValidityClaims | O31: 99.954311 | Q31: Fail - Invalid Data | R31: Sprint40 | T31: =VLOOKUP(N31,Sheet1!W:X,2,FALSE) -> PASS
A32: Claims | B32: Invalid Data | C32: Invalid Data | D32: Invalid Data | E32: KDE00138 | F32: วันที่เกิดเหตุ | G32: occurred date | H32: claim | I32: cclaim | J32: oacm | K32: accidentdate | L32: Validity | M32: DQ Measurement Result - Claims.xlsx | N32: KDE00138claim.cclaim.oacm.accidentdateValidityClaims | O32: 99.998286 | Q32: Fail - Invalid Data | R32: Sprint40 | T32: =VLOOKUP(N32,Sheet1!W:X,2,FALSE) -> PASS
